{
 "cells": [
  {
   "cell_type": "code",
   "execution_count": 2,
   "id": "c6fd7003",
   "metadata": {},
   "outputs": [
    {
     "name": "stdout",
     "output_type": "stream",
     "text": [
      "ERROR! Session/line number was not unique in database. History logging moved to new session 42\n"
     ]
    }
   ],
   "source": [
    "import tensorflow as tf\n",
    "import pandas as pd\n",
    "import numpy as np\n",
    "import matplotlib.pyplot as plt\n",
    "from tensorflow import keras\n",
    "from tensorflow_core.python.keras import layers\n",
    "\n",
    "%matplotlib inline"
   ]
  },
  {
   "cell_type": "code",
   "execution_count": 3,
   "id": "f729b738",
   "metadata": {},
   "outputs": [
    {
     "name": "stdout",
     "output_type": "stream",
     "text": [
      "ERROR! Session/line number was not unique in database. History logging moved to new session 43\n"
     ]
    }
   ],
   "source": [
    "fashion_mnist = keras.datasets.fashion_mnist\n",
    "(train_images,train_labels),(test_images,test_labels)= fashion_mnist.load_data()"
   ]
  },
  {
   "cell_type": "code",
   "execution_count": 7,
   "id": "945e00fb",
   "metadata": {},
   "outputs": [
    {
     "name": "stderr",
     "output_type": "stream",
     "text": [
      "2021-11-15 14:49:26.003550: W tensorflow/stream_executor/platform/default/dso_loader.cc:55] Could not load dynamic library 'libcuda.so.1'; dlerror: libcuda.so.1: cannot open shared object file: No such file or directory\n",
      "2021-11-15 14:49:26.003569: E tensorflow/stream_executor/cuda/cuda_driver.cc:318] failed call to cuInit: UNKNOWN ERROR (303)\n",
      "2021-11-15 14:49:26.003602: I tensorflow/stream_executor/cuda/cuda_diagnostics.cc:156] kernel driver does not appear to be running on this host (mi-HP-ProDesk-680-G6-PCI-Microtower-PC): /proc/driver/nvidia/version does not exist\n",
      "2021-11-15 14:49:26.003732: I tensorflow/core/platform/cpu_feature_guard.cc:142] Your CPU supports instructions that this TensorFlow binary was not compiled to use: SSE4.1 SSE4.2 AVX AVX2 FMA\n",
      "2021-11-15 14:49:26.024234: I tensorflow/core/platform/profile_utils/cpu_utils.cc:94] CPU Frequency: 2899885000 Hz\n",
      "2021-11-15 14:49:26.024620: I tensorflow/compiler/xla/service/service.cc:168] XLA service 0x55ccbdd7e8f0 executing computations on platform Host. Devices:\n",
      "2021-11-15 14:49:26.024639: I tensorflow/compiler/xla/service/service.cc:175]   StreamExecutor device (0): Host, Default Version\n"
     ]
    }
   ],
   "source": [
    "model = tf.keras.Sequential()\n",
    "model.add(tf.keras.layers.Conv2D(32,(3,3),input_shape=(28,28,1),activation=\"relu\"))"
   ]
  },
  {
   "cell_type": "code",
   "execution_count": 8,
   "id": "600319b1",
   "metadata": {},
   "outputs": [
    {
     "data": {
      "text/plain": [
       "(None, 26, 26, 32)"
      ]
     },
     "execution_count": 8,
     "metadata": {},
     "output_type": "execute_result"
    }
   ],
   "source": [
    "model.output_shape  #32卷  默认不padding"
   ]
  },
  {
   "cell_type": "code",
   "execution_count": 9,
   "id": "fb36dbb0",
   "metadata": {},
   "outputs": [],
   "source": [
    "model = tf.keras.Sequential()\n",
    "model.add(tf.keras.layers.Conv2D(32,(3,3),input_shape=(28,28,1),activation=\"relu\",padding=\"same\"))"
   ]
  },
  {
   "cell_type": "code",
   "execution_count": 10,
   "id": "97880841",
   "metadata": {},
   "outputs": [
    {
     "data": {
      "text/plain": [
       "(None, 28, 28, 32)"
      ]
     },
     "execution_count": 10,
     "metadata": {},
     "output_type": "execute_result"
    }
   ],
   "source": [
    "model.output_shape"
   ]
  },
  {
   "cell_type": "code",
   "execution_count": 11,
   "id": "14c2e595",
   "metadata": {},
   "outputs": [],
   "source": [
    "model.add(tf.keras.layers.MaxPool2D()) #默认缩小一半"
   ]
  },
  {
   "cell_type": "code",
   "execution_count": 12,
   "id": "5ff60779",
   "metadata": {},
   "outputs": [
    {
     "data": {
      "text/plain": [
       "(None, 14, 14, 32)"
      ]
     },
     "execution_count": 12,
     "metadata": {},
     "output_type": "execute_result"
    }
   ],
   "source": [
    "model.output_shape"
   ]
  },
  {
   "cell_type": "code",
   "execution_count": 13,
   "id": "2f74e8c7",
   "metadata": {},
   "outputs": [],
   "source": [
    "model.add(tf.keras.layers.Conv2D(64,(3,3),activation=\"relu\"))"
   ]
  },
  {
   "cell_type": "code",
   "execution_count": 14,
   "id": "6f244700",
   "metadata": {},
   "outputs": [
    {
     "data": {
      "text/plain": [
       "(None, 12, 12, 64)"
      ]
     },
     "execution_count": 14,
     "metadata": {},
     "output_type": "execute_result"
    }
   ],
   "source": [
    "model.output_shape"
   ]
  },
  {
   "cell_type": "code",
   "execution_count": null,
   "id": "038911a4",
   "metadata": {},
   "outputs": [
    {
     "name": "stderr",
     "output_type": "stream",
     "text": [
      "ERROR:root:Internal Python error in the inspect module.\n",
      "Below is the traceback from this internal error.\n",
      "\n",
      "ERROR:root:Internal Python error in the inspect module.\n",
      "Below is the traceback from this internal error.\n",
      "\n",
      "ERROR:root:Internal Python error in the inspect module.\n",
      "Below is the traceback from this internal error.\n",
      "\n"
     ]
    },
    {
     "name": "stdout",
     "output_type": "stream",
     "text": [
      "Traceback (most recent call last):\n",
      "  File \"/home/mi/zpz/anaconda3/envs/tf_2.0_gpu/lib/python3.7/site-packages/IPython/core/interactiveshell.py\", line 3444, in run_code\n",
      "    exec(code_obj, self.user_global_ns, self.user_ns)\n",
      "  File \"/tmp/ipykernel_9431/4014305924.py\", line 1, in <module>\n",
      "    model.add(tf.keras.layers.GlobalAveragePooling2D())#全居池化  在所有纬度上进行平均 这样方便一会dense层连接 因为dense层值接受2维  而一般的flatten 效果不是很理想\n",
      "  File \"/home/mi/zpz/anaconda3/envs/tf_2.0_gpu/lib/python3.7/site-packages/tensorflow_core/python/training/tracking/base.py\", line 457, in _method_wrapper\n",
      "    result = method(self, *args, **kwargs)\n",
      "  File \"/home/mi/zpz/anaconda3/envs/tf_2.0_gpu/lib/python3.7/site-packages/tensorflow_core/python/keras/engine/sequential.py\", line 196, in add\n",
      "    output_tensor = layer(self.outputs[0])\n",
      "  File \"/home/mi/zpz/anaconda3/envs/tf_2.0_gpu/lib/python3.7/site-packages/tensorflow_core/python/keras/engine/base_layer.py\", line 812, in __call__\n",
      "    self.name)\n",
      "  File \"/home/mi/zpz/anaconda3/envs/tf_2.0_gpu/lib/python3.7/site-packages/tensorflow_core/python/keras/engine/input_spec.py\", line 177, in assert_input_compatibility\n",
      "    str(x.shape.as_list()))\n",
      "ValueError: Input 0 of layer global_average_pooling2d_1 is incompatible with the layer: expected ndim=4, found ndim=2. Full shape received: [None, 64]\n",
      "\n",
      "During handling of the above exception, another exception occurred:\n",
      "\n",
      "Traceback (most recent call last):\n",
      "  File \"/home/mi/zpz/anaconda3/envs/tf_2.0_gpu/lib/python3.7/site-packages/IPython/core/interactiveshell.py\", line 2064, in showtraceback\n",
      "    stb = value._render_traceback_()\n",
      "AttributeError: 'ValueError' object has no attribute '_render_traceback_'\n",
      "\n",
      "During handling of the above exception, another exception occurred:\n",
      "\n",
      "Traceback (most recent call last):\n",
      "  File \"/home/mi/zpz/anaconda3/envs/tf_2.0_gpu/lib/python3.7/site-packages/IPython/core/ultratb.py\", line 1101, in get_records\n",
      "    return _fixed_getinnerframes(etb, number_of_lines_of_context, tb_offset)\n",
      "  File \"/home/mi/zpz/anaconda3/envs/tf_2.0_gpu/lib/python3.7/site-packages/IPython/core/ultratb.py\", line 248, in wrapped\n",
      "    return f(*args, **kwargs)\n",
      "  File \"/home/mi/zpz/anaconda3/envs/tf_2.0_gpu/lib/python3.7/site-packages/IPython/core/ultratb.py\", line 281, in _fixed_getinnerframes\n",
      "    records = fix_frame_records_filenames(inspect.getinnerframes(etb, context))\n",
      "  File \"/home/mi/zpz/anaconda3/envs/tf_2.0_gpu/lib/python3.7/inspect.py\", line 1502, in getinnerframes\n",
      "    frameinfo = (tb.tb_frame,) + getframeinfo(tb, context)\n",
      "  File \"/home/mi/zpz/anaconda3/envs/tf_2.0_gpu/lib/python3.7/inspect.py\", line 1460, in getframeinfo\n",
      "    filename = getsourcefile(frame) or getfile(frame)\n",
      "  File \"/home/mi/zpz/anaconda3/envs/tf_2.0_gpu/lib/python3.7/inspect.py\", line 696, in getsourcefile\n",
      "    if getattr(getmodule(object, filename), '__loader__', None) is not None:\n",
      "  File \"/home/mi/zpz/anaconda3/envs/tf_2.0_gpu/lib/python3.7/inspect.py\", line 733, in getmodule\n",
      "    if ismodule(module) and hasattr(module, '__file__'):\n",
      "  File \"/home/mi/zpz/anaconda3/envs/tf_2.0_gpu/lib/python3.7/site-packages/tensorflow/__init__.py\", line 50, in __getattr__\n",
      "    module = self._load()\n",
      "  File \"/home/mi/zpz/anaconda3/envs/tf_2.0_gpu/lib/python3.7/site-packages/tensorflow/__init__.py\", line 44, in _load\n",
      "    module = _importlib.import_module(self.__name__)\n",
      "  File \"/home/mi/zpz/anaconda3/envs/tf_2.0_gpu/lib/python3.7/importlib/__init__.py\", line 127, in import_module\n",
      "    return _bootstrap._gcd_import(name[level:], package, level)\n",
      "  File \"<frozen importlib._bootstrap>\", line 1006, in _gcd_import\n",
      "  File \"<frozen importlib._bootstrap>\", line 983, in _find_and_load\n",
      "  File \"<frozen importlib._bootstrap>\", line 965, in _find_and_load_unlocked\n",
      "ModuleNotFoundError: No module named 'tensorflow_core.estimator'\n",
      "Traceback (most recent call last):\n",
      "  File \"/home/mi/zpz/anaconda3/envs/tf_2.0_gpu/lib/python3.7/site-packages/IPython/core/interactiveshell.py\", line 3444, in run_code\n",
      "    exec(code_obj, self.user_global_ns, self.user_ns)\n",
      "  File \"/tmp/ipykernel_9431/4014305924.py\", line 1, in <module>\n",
      "    model.add(tf.keras.layers.GlobalAveragePooling2D())#全居池化  在所有纬度上进行平均 这样方便一会dense层连接 因为dense层值接受2维  而一般的flatten 效果不是很理想\n",
      "  File \"/home/mi/zpz/anaconda3/envs/tf_2.0_gpu/lib/python3.7/site-packages/tensorflow_core/python/training/tracking/base.py\", line 457, in _method_wrapper\n",
      "    result = method(self, *args, **kwargs)\n",
      "  File \"/home/mi/zpz/anaconda3/envs/tf_2.0_gpu/lib/python3.7/site-packages/tensorflow_core/python/keras/engine/sequential.py\", line 196, in add\n",
      "    output_tensor = layer(self.outputs[0])\n",
      "  File \"/home/mi/zpz/anaconda3/envs/tf_2.0_gpu/lib/python3.7/site-packages/tensorflow_core/python/keras/engine/base_layer.py\", line 812, in __call__\n",
      "    self.name)\n",
      "  File \"/home/mi/zpz/anaconda3/envs/tf_2.0_gpu/lib/python3.7/site-packages/tensorflow_core/python/keras/engine/input_spec.py\", line 177, in assert_input_compatibility\n",
      "    str(x.shape.as_list()))\n",
      "ValueError: Input 0 of layer global_average_pooling2d_1 is incompatible with the layer: expected ndim=4, found ndim=2. Full shape received: [None, 64]\n",
      "\n",
      "During handling of the above exception, another exception occurred:\n",
      "\n",
      "Traceback (most recent call last):\n",
      "  File \"/home/mi/zpz/anaconda3/envs/tf_2.0_gpu/lib/python3.7/site-packages/IPython/core/interactiveshell.py\", line 2064, in showtraceback\n",
      "    stb = value._render_traceback_()\n",
      "AttributeError: 'ValueError' object has no attribute '_render_traceback_'\n",
      "\n",
      "During handling of the above exception, another exception occurred:\n",
      "\n",
      "Traceback (most recent call last):\n",
      "  File \"/home/mi/zpz/anaconda3/envs/tf_2.0_gpu/lib/python3.7/site-packages/IPython/core/interactiveshell.py\", line 3364, in run_ast_nodes\n",
      "    if (await self.run_code(code, result,  async_=asy)):\n",
      "  File \"/home/mi/zpz/anaconda3/envs/tf_2.0_gpu/lib/python3.7/site-packages/IPython/core/interactiveshell.py\", line 3461, in run_code\n",
      "    self.showtraceback(running_compiled_code=True)\n",
      "  File \"/home/mi/zpz/anaconda3/envs/tf_2.0_gpu/lib/python3.7/site-packages/IPython/core/interactiveshell.py\", line 2067, in showtraceback\n",
      "    value, tb, tb_offset=tb_offset)\n",
      "  File \"/home/mi/zpz/anaconda3/envs/tf_2.0_gpu/lib/python3.7/site-packages/IPython/core/ultratb.py\", line 1368, in structured_traceback\n",
      "    self, etype, value, tb, tb_offset, number_of_lines_of_context)\n",
      "  File \"/home/mi/zpz/anaconda3/envs/tf_2.0_gpu/lib/python3.7/site-packages/IPython/core/ultratb.py\", line 1268, in structured_traceback\n",
      "    self, etype, value, tb, tb_offset, number_of_lines_of_context\n",
      "  File \"/home/mi/zpz/anaconda3/envs/tf_2.0_gpu/lib/python3.7/site-packages/IPython/core/ultratb.py\", line 1125, in structured_traceback\n",
      "    tb_offset)\n",
      "  File \"/home/mi/zpz/anaconda3/envs/tf_2.0_gpu/lib/python3.7/site-packages/IPython/core/ultratb.py\", line 1082, in format_exception_as_a_whole\n",
      "    last_unique, recursion_repeat = find_recursion(orig_etype, evalue, records)\n",
      "  File \"/home/mi/zpz/anaconda3/envs/tf_2.0_gpu/lib/python3.7/site-packages/IPython/core/ultratb.py\", line 382, in find_recursion\n",
      "    return len(records), 0\n",
      "TypeError: object of type 'NoneType' has no len()\n",
      "\n",
      "During handling of the above exception, another exception occurred:\n",
      "\n",
      "Traceback (most recent call last):\n",
      "  File \"/home/mi/zpz/anaconda3/envs/tf_2.0_gpu/lib/python3.7/site-packages/IPython/core/interactiveshell.py\", line 2064, in showtraceback\n",
      "    stb = value._render_traceback_()\n",
      "AttributeError: 'TypeError' object has no attribute '_render_traceback_'\n",
      "\n",
      "During handling of the above exception, another exception occurred:\n",
      "\n",
      "Traceback (most recent call last):\n",
      "  File \"/home/mi/zpz/anaconda3/envs/tf_2.0_gpu/lib/python3.7/site-packages/IPython/core/ultratb.py\", line 1101, in get_records\n",
      "    return _fixed_getinnerframes(etb, number_of_lines_of_context, tb_offset)\n",
      "  File \"/home/mi/zpz/anaconda3/envs/tf_2.0_gpu/lib/python3.7/site-packages/IPython/core/ultratb.py\", line 248, in wrapped\n",
      "    return f(*args, **kwargs)\n",
      "  File \"/home/mi/zpz/anaconda3/envs/tf_2.0_gpu/lib/python3.7/site-packages/IPython/core/ultratb.py\", line 281, in _fixed_getinnerframes\n",
      "    records = fix_frame_records_filenames(inspect.getinnerframes(etb, context))\n",
      "  File \"/home/mi/zpz/anaconda3/envs/tf_2.0_gpu/lib/python3.7/inspect.py\", line 1502, in getinnerframes\n",
      "    frameinfo = (tb.tb_frame,) + getframeinfo(tb, context)\n",
      "  File \"/home/mi/zpz/anaconda3/envs/tf_2.0_gpu/lib/python3.7/inspect.py\", line 1460, in getframeinfo\n",
      "    filename = getsourcefile(frame) or getfile(frame)\n",
      "  File \"/home/mi/zpz/anaconda3/envs/tf_2.0_gpu/lib/python3.7/inspect.py\", line 696, in getsourcefile\n",
      "    if getattr(getmodule(object, filename), '__loader__', None) is not None:\n",
      "  File \"/home/mi/zpz/anaconda3/envs/tf_2.0_gpu/lib/python3.7/inspect.py\", line 733, in getmodule\n",
      "    if ismodule(module) and hasattr(module, '__file__'):\n",
      "  File \"/home/mi/zpz/anaconda3/envs/tf_2.0_gpu/lib/python3.7/site-packages/tensorflow/__init__.py\", line 50, in __getattr__\n",
      "    module = self._load()\n",
      "  File \"/home/mi/zpz/anaconda3/envs/tf_2.0_gpu/lib/python3.7/site-packages/tensorflow/__init__.py\", line 44, in _load\n",
      "    module = _importlib.import_module(self.__name__)\n",
      "  File \"/home/mi/zpz/anaconda3/envs/tf_2.0_gpu/lib/python3.7/importlib/__init__.py\", line 127, in import_module\n",
      "    return _bootstrap._gcd_import(name[level:], package, level)\n",
      "  File \"<frozen importlib._bootstrap>\", line 1006, in _gcd_import\n",
      "  File \"<frozen importlib._bootstrap>\", line 983, in _find_and_load\n",
      "  File \"<frozen importlib._bootstrap>\", line 965, in _find_and_load_unlocked\n",
      "ModuleNotFoundError: No module named 'tensorflow_core.estimator'\n",
      "Traceback (most recent call last):\n",
      "  File \"/home/mi/zpz/anaconda3/envs/tf_2.0_gpu/lib/python3.7/site-packages/IPython/core/interactiveshell.py\", line 3444, in run_code\n",
      "    exec(code_obj, self.user_global_ns, self.user_ns)\n",
      "  File \"/tmp/ipykernel_9431/4014305924.py\", line 1, in <module>\n",
      "    model.add(tf.keras.layers.GlobalAveragePooling2D())#全居池化  在所有纬度上进行平均 这样方便一会dense层连接 因为dense层值接受2维  而一般的flatten 效果不是很理想\n",
      "  File \"/home/mi/zpz/anaconda3/envs/tf_2.0_gpu/lib/python3.7/site-packages/tensorflow_core/python/training/tracking/base.py\", line 457, in _method_wrapper\n",
      "    result = method(self, *args, **kwargs)\n",
      "  File \"/home/mi/zpz/anaconda3/envs/tf_2.0_gpu/lib/python3.7/site-packages/tensorflow_core/python/keras/engine/sequential.py\", line 196, in add\n",
      "    output_tensor = layer(self.outputs[0])\n",
      "  File \"/home/mi/zpz/anaconda3/envs/tf_2.0_gpu/lib/python3.7/site-packages/tensorflow_core/python/keras/engine/base_layer.py\", line 812, in __call__\n",
      "    self.name)\n",
      "  File \"/home/mi/zpz/anaconda3/envs/tf_2.0_gpu/lib/python3.7/site-packages/tensorflow_core/python/keras/engine/input_spec.py\", line 177, in assert_input_compatibility\n",
      "    str(x.shape.as_list()))\n",
      "ValueError: Input 0 of layer global_average_pooling2d_1 is incompatible with the layer: expected ndim=4, found ndim=2. Full shape received: [None, 64]\n",
      "\n",
      "During handling of the above exception, another exception occurred:\n",
      "\n",
      "Traceback (most recent call last):\n",
      "  File \"/home/mi/zpz/anaconda3/envs/tf_2.0_gpu/lib/python3.7/site-packages/IPython/core/interactiveshell.py\", line 2064, in showtraceback\n",
      "    stb = value._render_traceback_()\n",
      "AttributeError: 'ValueError' object has no attribute '_render_traceback_'\n",
      "\n",
      "During handling of the above exception, another exception occurred:\n",
      "\n",
      "Traceback (most recent call last):\n",
      "  File \"/home/mi/zpz/anaconda3/envs/tf_2.0_gpu/lib/python3.7/site-packages/IPython/core/interactiveshell.py\", line 3364, in run_ast_nodes\n",
      "    if (await self.run_code(code, result,  async_=asy)):\n",
      "  File \"/home/mi/zpz/anaconda3/envs/tf_2.0_gpu/lib/python3.7/site-packages/IPython/core/interactiveshell.py\", line 3461, in run_code\n",
      "    self.showtraceback(running_compiled_code=True)\n",
      "  File \"/home/mi/zpz/anaconda3/envs/tf_2.0_gpu/lib/python3.7/site-packages/IPython/core/interactiveshell.py\", line 2067, in showtraceback\n",
      "    value, tb, tb_offset=tb_offset)\n",
      "  File \"/home/mi/zpz/anaconda3/envs/tf_2.0_gpu/lib/python3.7/site-packages/IPython/core/ultratb.py\", line 1368, in structured_traceback\n",
      "    self, etype, value, tb, tb_offset, number_of_lines_of_context)\n",
      "  File \"/home/mi/zpz/anaconda3/envs/tf_2.0_gpu/lib/python3.7/site-packages/IPython/core/ultratb.py\", line 1268, in structured_traceback\n",
      "    self, etype, value, tb, tb_offset, number_of_lines_of_context\n",
      "  File \"/home/mi/zpz/anaconda3/envs/tf_2.0_gpu/lib/python3.7/site-packages/IPython/core/ultratb.py\", line 1125, in structured_traceback\n",
      "    tb_offset)\n",
      "  File \"/home/mi/zpz/anaconda3/envs/tf_2.0_gpu/lib/python3.7/site-packages/IPython/core/ultratb.py\", line 1082, in format_exception_as_a_whole\n",
      "    last_unique, recursion_repeat = find_recursion(orig_etype, evalue, records)\n",
      "  File \"/home/mi/zpz/anaconda3/envs/tf_2.0_gpu/lib/python3.7/site-packages/IPython/core/ultratb.py\", line 382, in find_recursion\n",
      "    return len(records), 0\n",
      "TypeError: object of type 'NoneType' has no len()\n",
      "\n",
      "During handling of the above exception, another exception occurred:\n",
      "\n",
      "Traceback (most recent call last):\n",
      "  File \"/home/mi/zpz/anaconda3/envs/tf_2.0_gpu/lib/python3.7/site-packages/IPython/core/interactiveshell.py\", line 2064, in showtraceback\n",
      "    stb = value._render_traceback_()\n",
      "AttributeError: 'TypeError' object has no attribute '_render_traceback_'\n",
      "\n",
      "During handling of the above exception, another exception occurred:\n",
      "\n",
      "Traceback (most recent call last):\n",
      "  File \"/home/mi/zpz/anaconda3/envs/tf_2.0_gpu/lib/python3.7/site-packages/IPython/core/interactiveshell.py\", line 2947, in _run_cell\n",
      "    return runner(coro)\n",
      "  File \"/home/mi/zpz/anaconda3/envs/tf_2.0_gpu/lib/python3.7/site-packages/IPython/core/async_helpers.py\", line 68, in _pseudo_sync_runner\n",
      "    coro.send(None)\n",
      "  File \"/home/mi/zpz/anaconda3/envs/tf_2.0_gpu/lib/python3.7/site-packages/IPython/core/interactiveshell.py\", line 3173, in run_cell_async\n",
      "    interactivity=interactivity, compiler=compiler, result=result)\n",
      "  File \"/home/mi/zpz/anaconda3/envs/tf_2.0_gpu/lib/python3.7/site-packages/IPython/core/interactiveshell.py\", line 3383, in run_ast_nodes\n",
      "    self.showtraceback()\n",
      "  File \"/home/mi/zpz/anaconda3/envs/tf_2.0_gpu/lib/python3.7/site-packages/IPython/core/interactiveshell.py\", line 2067, in showtraceback\n",
      "    value, tb, tb_offset=tb_offset)\n",
      "  File \"/home/mi/zpz/anaconda3/envs/tf_2.0_gpu/lib/python3.7/site-packages/IPython/core/ultratb.py\", line 1368, in structured_traceback\n",
      "    self, etype, value, tb, tb_offset, number_of_lines_of_context)\n",
      "  File \"/home/mi/zpz/anaconda3/envs/tf_2.0_gpu/lib/python3.7/site-packages/IPython/core/ultratb.py\", line 1268, in structured_traceback\n",
      "    self, etype, value, tb, tb_offset, number_of_lines_of_context\n",
      "  File \"/home/mi/zpz/anaconda3/envs/tf_2.0_gpu/lib/python3.7/site-packages/IPython/core/ultratb.py\", line 1143, in structured_traceback\n",
      "    chained_exceptions_tb_offset)\n",
      "  File \"/home/mi/zpz/anaconda3/envs/tf_2.0_gpu/lib/python3.7/site-packages/IPython/core/ultratb.py\", line 1082, in format_exception_as_a_whole\n",
      "    last_unique, recursion_repeat = find_recursion(orig_etype, evalue, records)\n",
      "  File \"/home/mi/zpz/anaconda3/envs/tf_2.0_gpu/lib/python3.7/site-packages/IPython/core/ultratb.py\", line 382, in find_recursion\n",
      "    return len(records), 0\n",
      "TypeError: object of type 'NoneType' has no len()\n",
      "\n",
      "During handling of the above exception, another exception occurred:\n",
      "\n",
      "Traceback (most recent call last):\n",
      "  File \"/home/mi/zpz/anaconda3/envs/tf_2.0_gpu/lib/python3.7/site-packages/IPython/core/interactiveshell.py\", line 2064, in showtraceback\n",
      "    stb = value._render_traceback_()\n",
      "AttributeError: 'TypeError' object has no attribute '_render_traceback_'\n",
      "\n",
      "During handling of the above exception, another exception occurred:\n",
      "\n",
      "Traceback (most recent call last):\n",
      "  File \"/home/mi/zpz/anaconda3/envs/tf_2.0_gpu/lib/python3.7/site-packages/IPython/core/ultratb.py\", line 1101, in get_records\n",
      "    return _fixed_getinnerframes(etb, number_of_lines_of_context, tb_offset)\n",
      "  File \"/home/mi/zpz/anaconda3/envs/tf_2.0_gpu/lib/python3.7/site-packages/IPython/core/ultratb.py\", line 248, in wrapped\n",
      "    return f(*args, **kwargs)\n",
      "  File \"/home/mi/zpz/anaconda3/envs/tf_2.0_gpu/lib/python3.7/site-packages/IPython/core/ultratb.py\", line 281, in _fixed_getinnerframes\n",
      "    records = fix_frame_records_filenames(inspect.getinnerframes(etb, context))\n",
      "  File \"/home/mi/zpz/anaconda3/envs/tf_2.0_gpu/lib/python3.7/inspect.py\", line 1502, in getinnerframes\n",
      "    frameinfo = (tb.tb_frame,) + getframeinfo(tb, context)\n",
      "  File \"/home/mi/zpz/anaconda3/envs/tf_2.0_gpu/lib/python3.7/inspect.py\", line 1460, in getframeinfo\n",
      "    filename = getsourcefile(frame) or getfile(frame)\n",
      "  File \"/home/mi/zpz/anaconda3/envs/tf_2.0_gpu/lib/python3.7/inspect.py\", line 696, in getsourcefile\n",
      "    if getattr(getmodule(object, filename), '__loader__', None) is not None:\n",
      "  File \"/home/mi/zpz/anaconda3/envs/tf_2.0_gpu/lib/python3.7/inspect.py\", line 733, in getmodule\n",
      "    if ismodule(module) and hasattr(module, '__file__'):\n",
      "  File \"/home/mi/zpz/anaconda3/envs/tf_2.0_gpu/lib/python3.7/site-packages/tensorflow/__init__.py\", line 50, in __getattr__\n",
      "    module = self._load()\n",
      "  File \"/home/mi/zpz/anaconda3/envs/tf_2.0_gpu/lib/python3.7/site-packages/tensorflow/__init__.py\", line 44, in _load\n",
      "    module = _importlib.import_module(self.__name__)\n",
      "  File \"/home/mi/zpz/anaconda3/envs/tf_2.0_gpu/lib/python3.7/importlib/__init__.py\", line 127, in import_module\n",
      "    return _bootstrap._gcd_import(name[level:], package, level)\n",
      "  File \"<frozen importlib._bootstrap>\", line 1006, in _gcd_import\n",
      "  File \"<frozen importlib._bootstrap>\", line 983, in _find_and_load\n",
      "  File \"<frozen importlib._bootstrap>\", line 965, in _find_and_load_unlocked\n",
      "ModuleNotFoundError: No module named 'tensorflow_core.estimator'\n"
     ]
    }
   ],
   "source": [
    "model.add(tf.keras.layers.GlobalAveragePooling2D())#全居池化  在所有纬度上进行平均 这样方便一会dense层连接 因为dense层值接受2维  而一般的flatten 效果不是很理想"
   ]
  },
  {
   "cell_type": "code",
   "execution_count": 17,
   "id": "6c8dc6d3",
   "metadata": {},
   "outputs": [
    {
     "data": {
      "text/plain": [
       "(None, 64)"
      ]
     },
     "execution_count": 17,
     "metadata": {},
     "output_type": "execute_result"
    },
    {
     "name": "stdout",
     "output_type": "stream",
     "text": [
      "ERROR! Session/line number was not unique in database. History logging moved to new session 45\n"
     ]
    }
   ],
   "source": [
    "model.output_shape"
   ]
  },
  {
   "cell_type": "code",
   "execution_count": null,
   "id": "d418dc37",
   "metadata": {},
   "outputs": [
    {
     "name": "stderr",
     "output_type": "stream",
     "text": [
      "ERROR:root:Internal Python error in the inspect module.\n",
      "Below is the traceback from this internal error.\n",
      "\n",
      "ERROR:root:Internal Python error in the inspect module.\n",
      "Below is the traceback from this internal error.\n",
      "\n",
      "ERROR:root:Internal Python error in the inspect module.\n",
      "Below is the traceback from this internal error.\n",
      "\n"
     ]
    },
    {
     "name": "stdout",
     "output_type": "stream",
     "text": [
      "Traceback (most recent call last):\n",
      "  File \"/home/mi/zpz/anaconda3/envs/tf_2.0_gpu/lib/python3.7/site-packages/IPython/core/interactiveshell.py\", line 3444, in run_code\n",
      "    exec(code_obj, self.user_global_ns, self.user_ns)\n",
      "  File \"/tmp/ipykernel_9431/3790734560.py\", line 4, in <module>\n",
      "    model.add(tf.keras.layers.Conv2D(64,(3,3),input_shape=train_images.shape[1:],activation=\"relu\",padding=\"same\"))\n",
      "  File \"/home/mi/zpz/anaconda3/envs/tf_2.0_gpu/lib/python3.7/site-packages/tensorflow_core/python/training/tracking/base.py\", line 457, in _method_wrapper\n",
      "    result = method(self, *args, **kwargs)\n",
      "  File \"/home/mi/zpz/anaconda3/envs/tf_2.0_gpu/lib/python3.7/site-packages/tensorflow_core/python/keras/engine/sequential.py\", line 178, in add\n",
      "    layer(x)\n",
      "  File \"/home/mi/zpz/anaconda3/envs/tf_2.0_gpu/lib/python3.7/site-packages/tensorflow_core/python/keras/engine/base_layer.py\", line 812, in __call__\n",
      "    self.name)\n",
      "  File \"/home/mi/zpz/anaconda3/envs/tf_2.0_gpu/lib/python3.7/site-packages/tensorflow_core/python/keras/engine/input_spec.py\", line 177, in assert_input_compatibility\n",
      "    str(x.shape.as_list()))\n",
      "ValueError: Input 0 of layer conv2d_4 is incompatible with the layer: expected ndim=4, found ndim=3. Full shape received: [None, 28, 28]\n",
      "\n",
      "During handling of the above exception, another exception occurred:\n",
      "\n",
      "Traceback (most recent call last):\n",
      "  File \"/home/mi/zpz/anaconda3/envs/tf_2.0_gpu/lib/python3.7/site-packages/IPython/core/interactiveshell.py\", line 2064, in showtraceback\n",
      "    stb = value._render_traceback_()\n",
      "AttributeError: 'ValueError' object has no attribute '_render_traceback_'\n",
      "\n",
      "During handling of the above exception, another exception occurred:\n",
      "\n",
      "Traceback (most recent call last):\n",
      "  File \"/home/mi/zpz/anaconda3/envs/tf_2.0_gpu/lib/python3.7/site-packages/IPython/core/ultratb.py\", line 1101, in get_records\n",
      "    return _fixed_getinnerframes(etb, number_of_lines_of_context, tb_offset)\n",
      "  File \"/home/mi/zpz/anaconda3/envs/tf_2.0_gpu/lib/python3.7/site-packages/IPython/core/ultratb.py\", line 248, in wrapped\n",
      "    return f(*args, **kwargs)\n",
      "  File \"/home/mi/zpz/anaconda3/envs/tf_2.0_gpu/lib/python3.7/site-packages/IPython/core/ultratb.py\", line 281, in _fixed_getinnerframes\n",
      "    records = fix_frame_records_filenames(inspect.getinnerframes(etb, context))\n",
      "  File \"/home/mi/zpz/anaconda3/envs/tf_2.0_gpu/lib/python3.7/inspect.py\", line 1502, in getinnerframes\n",
      "    frameinfo = (tb.tb_frame,) + getframeinfo(tb, context)\n",
      "  File \"/home/mi/zpz/anaconda3/envs/tf_2.0_gpu/lib/python3.7/inspect.py\", line 1460, in getframeinfo\n",
      "    filename = getsourcefile(frame) or getfile(frame)\n",
      "  File \"/home/mi/zpz/anaconda3/envs/tf_2.0_gpu/lib/python3.7/inspect.py\", line 696, in getsourcefile\n",
      "    if getattr(getmodule(object, filename), '__loader__', None) is not None:\n",
      "  File \"/home/mi/zpz/anaconda3/envs/tf_2.0_gpu/lib/python3.7/inspect.py\", line 733, in getmodule\n",
      "    if ismodule(module) and hasattr(module, '__file__'):\n",
      "  File \"/home/mi/zpz/anaconda3/envs/tf_2.0_gpu/lib/python3.7/site-packages/tensorflow/__init__.py\", line 50, in __getattr__\n",
      "    module = self._load()\n",
      "  File \"/home/mi/zpz/anaconda3/envs/tf_2.0_gpu/lib/python3.7/site-packages/tensorflow/__init__.py\", line 44, in _load\n",
      "    module = _importlib.import_module(self.__name__)\n",
      "  File \"/home/mi/zpz/anaconda3/envs/tf_2.0_gpu/lib/python3.7/importlib/__init__.py\", line 127, in import_module\n",
      "    return _bootstrap._gcd_import(name[level:], package, level)\n",
      "  File \"<frozen importlib._bootstrap>\", line 1006, in _gcd_import\n",
      "  File \"<frozen importlib._bootstrap>\", line 983, in _find_and_load\n",
      "  File \"<frozen importlib._bootstrap>\", line 965, in _find_and_load_unlocked\n",
      "ModuleNotFoundError: No module named 'tensorflow_core.estimator'\n",
      "Traceback (most recent call last):\n",
      "  File \"/home/mi/zpz/anaconda3/envs/tf_2.0_gpu/lib/python3.7/site-packages/IPython/core/interactiveshell.py\", line 3444, in run_code\n",
      "    exec(code_obj, self.user_global_ns, self.user_ns)\n",
      "  File \"/tmp/ipykernel_9431/3790734560.py\", line 4, in <module>\n",
      "    model.add(tf.keras.layers.Conv2D(64,(3,3),input_shape=train_images.shape[1:],activation=\"relu\",padding=\"same\"))\n",
      "  File \"/home/mi/zpz/anaconda3/envs/tf_2.0_gpu/lib/python3.7/site-packages/tensorflow_core/python/training/tracking/base.py\", line 457, in _method_wrapper\n",
      "    result = method(self, *args, **kwargs)\n",
      "  File \"/home/mi/zpz/anaconda3/envs/tf_2.0_gpu/lib/python3.7/site-packages/tensorflow_core/python/keras/engine/sequential.py\", line 178, in add\n",
      "    layer(x)\n",
      "  File \"/home/mi/zpz/anaconda3/envs/tf_2.0_gpu/lib/python3.7/site-packages/tensorflow_core/python/keras/engine/base_layer.py\", line 812, in __call__\n",
      "    self.name)\n",
      "  File \"/home/mi/zpz/anaconda3/envs/tf_2.0_gpu/lib/python3.7/site-packages/tensorflow_core/python/keras/engine/input_spec.py\", line 177, in assert_input_compatibility\n",
      "    str(x.shape.as_list()))\n",
      "ValueError: Input 0 of layer conv2d_4 is incompatible with the layer: expected ndim=4, found ndim=3. Full shape received: [None, 28, 28]\n",
      "\n",
      "During handling of the above exception, another exception occurred:\n",
      "\n",
      "Traceback (most recent call last):\n",
      "  File \"/home/mi/zpz/anaconda3/envs/tf_2.0_gpu/lib/python3.7/site-packages/IPython/core/interactiveshell.py\", line 2064, in showtraceback\n",
      "    stb = value._render_traceback_()\n",
      "AttributeError: 'ValueError' object has no attribute '_render_traceback_'\n",
      "\n",
      "During handling of the above exception, another exception occurred:\n",
      "\n",
      "Traceback (most recent call last):\n",
      "  File \"/home/mi/zpz/anaconda3/envs/tf_2.0_gpu/lib/python3.7/site-packages/IPython/core/interactiveshell.py\", line 3364, in run_ast_nodes\n",
      "    if (await self.run_code(code, result,  async_=asy)):\n",
      "  File \"/home/mi/zpz/anaconda3/envs/tf_2.0_gpu/lib/python3.7/site-packages/IPython/core/interactiveshell.py\", line 3461, in run_code\n",
      "    self.showtraceback(running_compiled_code=True)\n",
      "  File \"/home/mi/zpz/anaconda3/envs/tf_2.0_gpu/lib/python3.7/site-packages/IPython/core/interactiveshell.py\", line 2067, in showtraceback\n",
      "    value, tb, tb_offset=tb_offset)\n",
      "  File \"/home/mi/zpz/anaconda3/envs/tf_2.0_gpu/lib/python3.7/site-packages/IPython/core/ultratb.py\", line 1368, in structured_traceback\n",
      "    self, etype, value, tb, tb_offset, number_of_lines_of_context)\n",
      "  File \"/home/mi/zpz/anaconda3/envs/tf_2.0_gpu/lib/python3.7/site-packages/IPython/core/ultratb.py\", line 1268, in structured_traceback\n",
      "    self, etype, value, tb, tb_offset, number_of_lines_of_context\n",
      "  File \"/home/mi/zpz/anaconda3/envs/tf_2.0_gpu/lib/python3.7/site-packages/IPython/core/ultratb.py\", line 1125, in structured_traceback\n",
      "    tb_offset)\n",
      "  File \"/home/mi/zpz/anaconda3/envs/tf_2.0_gpu/lib/python3.7/site-packages/IPython/core/ultratb.py\", line 1082, in format_exception_as_a_whole\n",
      "    last_unique, recursion_repeat = find_recursion(orig_etype, evalue, records)\n",
      "  File \"/home/mi/zpz/anaconda3/envs/tf_2.0_gpu/lib/python3.7/site-packages/IPython/core/ultratb.py\", line 382, in find_recursion\n",
      "    return len(records), 0\n",
      "TypeError: object of type 'NoneType' has no len()\n",
      "\n",
      "During handling of the above exception, another exception occurred:\n",
      "\n",
      "Traceback (most recent call last):\n",
      "  File \"/home/mi/zpz/anaconda3/envs/tf_2.0_gpu/lib/python3.7/site-packages/IPython/core/interactiveshell.py\", line 2064, in showtraceback\n",
      "    stb = value._render_traceback_()\n",
      "AttributeError: 'TypeError' object has no attribute '_render_traceback_'\n",
      "\n",
      "During handling of the above exception, another exception occurred:\n",
      "\n",
      "Traceback (most recent call last):\n",
      "  File \"/home/mi/zpz/anaconda3/envs/tf_2.0_gpu/lib/python3.7/site-packages/IPython/core/ultratb.py\", line 1101, in get_records\n",
      "    return _fixed_getinnerframes(etb, number_of_lines_of_context, tb_offset)\n",
      "  File \"/home/mi/zpz/anaconda3/envs/tf_2.0_gpu/lib/python3.7/site-packages/IPython/core/ultratb.py\", line 248, in wrapped\n",
      "    return f(*args, **kwargs)\n",
      "  File \"/home/mi/zpz/anaconda3/envs/tf_2.0_gpu/lib/python3.7/site-packages/IPython/core/ultratb.py\", line 281, in _fixed_getinnerframes\n",
      "    records = fix_frame_records_filenames(inspect.getinnerframes(etb, context))\n",
      "  File \"/home/mi/zpz/anaconda3/envs/tf_2.0_gpu/lib/python3.7/inspect.py\", line 1502, in getinnerframes\n",
      "    frameinfo = (tb.tb_frame,) + getframeinfo(tb, context)\n",
      "  File \"/home/mi/zpz/anaconda3/envs/tf_2.0_gpu/lib/python3.7/inspect.py\", line 1460, in getframeinfo\n",
      "    filename = getsourcefile(frame) or getfile(frame)\n",
      "  File \"/home/mi/zpz/anaconda3/envs/tf_2.0_gpu/lib/python3.7/inspect.py\", line 696, in getsourcefile\n",
      "    if getattr(getmodule(object, filename), '__loader__', None) is not None:\n",
      "  File \"/home/mi/zpz/anaconda3/envs/tf_2.0_gpu/lib/python3.7/inspect.py\", line 733, in getmodule\n",
      "    if ismodule(module) and hasattr(module, '__file__'):\n",
      "  File \"/home/mi/zpz/anaconda3/envs/tf_2.0_gpu/lib/python3.7/site-packages/tensorflow/__init__.py\", line 50, in __getattr__\n",
      "    module = self._load()\n",
      "  File \"/home/mi/zpz/anaconda3/envs/tf_2.0_gpu/lib/python3.7/site-packages/tensorflow/__init__.py\", line 44, in _load\n",
      "    module = _importlib.import_module(self.__name__)\n",
      "  File \"/home/mi/zpz/anaconda3/envs/tf_2.0_gpu/lib/python3.7/importlib/__init__.py\", line 127, in import_module\n",
      "    return _bootstrap._gcd_import(name[level:], package, level)\n",
      "  File \"<frozen importlib._bootstrap>\", line 1006, in _gcd_import\n",
      "  File \"<frozen importlib._bootstrap>\", line 983, in _find_and_load\n",
      "  File \"<frozen importlib._bootstrap>\", line 965, in _find_and_load_unlocked\n",
      "ModuleNotFoundError: No module named 'tensorflow_core.estimator'\n",
      "Traceback (most recent call last):\n",
      "  File \"/home/mi/zpz/anaconda3/envs/tf_2.0_gpu/lib/python3.7/site-packages/IPython/core/interactiveshell.py\", line 3444, in run_code\n",
      "    exec(code_obj, self.user_global_ns, self.user_ns)\n",
      "  File \"/tmp/ipykernel_9431/3790734560.py\", line 4, in <module>\n",
      "    model.add(tf.keras.layers.Conv2D(64,(3,3),input_shape=train_images.shape[1:],activation=\"relu\",padding=\"same\"))\n",
      "  File \"/home/mi/zpz/anaconda3/envs/tf_2.0_gpu/lib/python3.7/site-packages/tensorflow_core/python/training/tracking/base.py\", line 457, in _method_wrapper\n",
      "    result = method(self, *args, **kwargs)\n",
      "  File \"/home/mi/zpz/anaconda3/envs/tf_2.0_gpu/lib/python3.7/site-packages/tensorflow_core/python/keras/engine/sequential.py\", line 178, in add\n",
      "    layer(x)\n",
      "  File \"/home/mi/zpz/anaconda3/envs/tf_2.0_gpu/lib/python3.7/site-packages/tensorflow_core/python/keras/engine/base_layer.py\", line 812, in __call__\n",
      "    self.name)\n",
      "  File \"/home/mi/zpz/anaconda3/envs/tf_2.0_gpu/lib/python3.7/site-packages/tensorflow_core/python/keras/engine/input_spec.py\", line 177, in assert_input_compatibility\n",
      "    str(x.shape.as_list()))\n",
      "ValueError: Input 0 of layer conv2d_4 is incompatible with the layer: expected ndim=4, found ndim=3. Full shape received: [None, 28, 28]\n",
      "\n",
      "During handling of the above exception, another exception occurred:\n",
      "\n",
      "Traceback (most recent call last):\n",
      "  File \"/home/mi/zpz/anaconda3/envs/tf_2.0_gpu/lib/python3.7/site-packages/IPython/core/interactiveshell.py\", line 2064, in showtraceback\n",
      "    stb = value._render_traceback_()\n",
      "AttributeError: 'ValueError' object has no attribute '_render_traceback_'\n",
      "\n",
      "During handling of the above exception, another exception occurred:\n",
      "\n",
      "Traceback (most recent call last):\n",
      "  File \"/home/mi/zpz/anaconda3/envs/tf_2.0_gpu/lib/python3.7/site-packages/IPython/core/interactiveshell.py\", line 3364, in run_ast_nodes\n",
      "    if (await self.run_code(code, result,  async_=asy)):\n",
      "  File \"/home/mi/zpz/anaconda3/envs/tf_2.0_gpu/lib/python3.7/site-packages/IPython/core/interactiveshell.py\", line 3461, in run_code\n",
      "    self.showtraceback(running_compiled_code=True)\n",
      "  File \"/home/mi/zpz/anaconda3/envs/tf_2.0_gpu/lib/python3.7/site-packages/IPython/core/interactiveshell.py\", line 2067, in showtraceback\n",
      "    value, tb, tb_offset=tb_offset)\n",
      "  File \"/home/mi/zpz/anaconda3/envs/tf_2.0_gpu/lib/python3.7/site-packages/IPython/core/ultratb.py\", line 1368, in structured_traceback\n",
      "    self, etype, value, tb, tb_offset, number_of_lines_of_context)\n",
      "  File \"/home/mi/zpz/anaconda3/envs/tf_2.0_gpu/lib/python3.7/site-packages/IPython/core/ultratb.py\", line 1268, in structured_traceback\n",
      "    self, etype, value, tb, tb_offset, number_of_lines_of_context\n",
      "  File \"/home/mi/zpz/anaconda3/envs/tf_2.0_gpu/lib/python3.7/site-packages/IPython/core/ultratb.py\", line 1125, in structured_traceback\n",
      "    tb_offset)\n",
      "  File \"/home/mi/zpz/anaconda3/envs/tf_2.0_gpu/lib/python3.7/site-packages/IPython/core/ultratb.py\", line 1082, in format_exception_as_a_whole\n",
      "    last_unique, recursion_repeat = find_recursion(orig_etype, evalue, records)\n",
      "  File \"/home/mi/zpz/anaconda3/envs/tf_2.0_gpu/lib/python3.7/site-packages/IPython/core/ultratb.py\", line 382, in find_recursion\n",
      "    return len(records), 0\n",
      "TypeError: object of type 'NoneType' has no len()\n",
      "\n",
      "During handling of the above exception, another exception occurred:\n",
      "\n",
      "Traceback (most recent call last):\n",
      "  File \"/home/mi/zpz/anaconda3/envs/tf_2.0_gpu/lib/python3.7/site-packages/IPython/core/interactiveshell.py\", line 2064, in showtraceback\n",
      "    stb = value._render_traceback_()\n",
      "AttributeError: 'TypeError' object has no attribute '_render_traceback_'\n",
      "\n",
      "During handling of the above exception, another exception occurred:\n",
      "\n",
      "Traceback (most recent call last):\n",
      "  File \"/home/mi/zpz/anaconda3/envs/tf_2.0_gpu/lib/python3.7/site-packages/IPython/core/interactiveshell.py\", line 2947, in _run_cell\n",
      "    return runner(coro)\n",
      "  File \"/home/mi/zpz/anaconda3/envs/tf_2.0_gpu/lib/python3.7/site-packages/IPython/core/async_helpers.py\", line 68, in _pseudo_sync_runner\n",
      "    coro.send(None)\n",
      "  File \"/home/mi/zpz/anaconda3/envs/tf_2.0_gpu/lib/python3.7/site-packages/IPython/core/interactiveshell.py\", line 3173, in run_cell_async\n",
      "    interactivity=interactivity, compiler=compiler, result=result)\n",
      "  File \"/home/mi/zpz/anaconda3/envs/tf_2.0_gpu/lib/python3.7/site-packages/IPython/core/interactiveshell.py\", line 3383, in run_ast_nodes\n",
      "    self.showtraceback()\n",
      "  File \"/home/mi/zpz/anaconda3/envs/tf_2.0_gpu/lib/python3.7/site-packages/IPython/core/interactiveshell.py\", line 2067, in showtraceback\n",
      "    value, tb, tb_offset=tb_offset)\n",
      "  File \"/home/mi/zpz/anaconda3/envs/tf_2.0_gpu/lib/python3.7/site-packages/IPython/core/ultratb.py\", line 1368, in structured_traceback\n",
      "    self, etype, value, tb, tb_offset, number_of_lines_of_context)\n",
      "  File \"/home/mi/zpz/anaconda3/envs/tf_2.0_gpu/lib/python3.7/site-packages/IPython/core/ultratb.py\", line 1268, in structured_traceback\n",
      "    self, etype, value, tb, tb_offset, number_of_lines_of_context\n",
      "  File \"/home/mi/zpz/anaconda3/envs/tf_2.0_gpu/lib/python3.7/site-packages/IPython/core/ultratb.py\", line 1143, in structured_traceback\n",
      "    chained_exceptions_tb_offset)\n",
      "  File \"/home/mi/zpz/anaconda3/envs/tf_2.0_gpu/lib/python3.7/site-packages/IPython/core/ultratb.py\", line 1082, in format_exception_as_a_whole\n",
      "    last_unique, recursion_repeat = find_recursion(orig_etype, evalue, records)\n",
      "  File \"/home/mi/zpz/anaconda3/envs/tf_2.0_gpu/lib/python3.7/site-packages/IPython/core/ultratb.py\", line 382, in find_recursion\n",
      "    return len(records), 0\n",
      "TypeError: object of type 'NoneType' has no len()\n",
      "\n",
      "During handling of the above exception, another exception occurred:\n",
      "\n",
      "Traceback (most recent call last):\n",
      "  File \"/home/mi/zpz/anaconda3/envs/tf_2.0_gpu/lib/python3.7/site-packages/IPython/core/interactiveshell.py\", line 2064, in showtraceback\n",
      "    stb = value._render_traceback_()\n",
      "AttributeError: 'TypeError' object has no attribute '_render_traceback_'\n",
      "\n",
      "During handling of the above exception, another exception occurred:\n",
      "\n",
      "Traceback (most recent call last):\n",
      "  File \"/home/mi/zpz/anaconda3/envs/tf_2.0_gpu/lib/python3.7/site-packages/IPython/core/ultratb.py\", line 1101, in get_records\n",
      "    return _fixed_getinnerframes(etb, number_of_lines_of_context, tb_offset)\n",
      "  File \"/home/mi/zpz/anaconda3/envs/tf_2.0_gpu/lib/python3.7/site-packages/IPython/core/ultratb.py\", line 248, in wrapped\n",
      "    return f(*args, **kwargs)\n",
      "  File \"/home/mi/zpz/anaconda3/envs/tf_2.0_gpu/lib/python3.7/site-packages/IPython/core/ultratb.py\", line 281, in _fixed_getinnerframes\n",
      "    records = fix_frame_records_filenames(inspect.getinnerframes(etb, context))\n",
      "  File \"/home/mi/zpz/anaconda3/envs/tf_2.0_gpu/lib/python3.7/inspect.py\", line 1502, in getinnerframes\n",
      "    frameinfo = (tb.tb_frame,) + getframeinfo(tb, context)\n",
      "  File \"/home/mi/zpz/anaconda3/envs/tf_2.0_gpu/lib/python3.7/inspect.py\", line 1460, in getframeinfo\n",
      "    filename = getsourcefile(frame) or getfile(frame)\n",
      "  File \"/home/mi/zpz/anaconda3/envs/tf_2.0_gpu/lib/python3.7/inspect.py\", line 696, in getsourcefile\n",
      "    if getattr(getmodule(object, filename), '__loader__', None) is not None:\n",
      "  File \"/home/mi/zpz/anaconda3/envs/tf_2.0_gpu/lib/python3.7/inspect.py\", line 733, in getmodule\n",
      "    if ismodule(module) and hasattr(module, '__file__'):\n",
      "  File \"/home/mi/zpz/anaconda3/envs/tf_2.0_gpu/lib/python3.7/site-packages/tensorflow/__init__.py\", line 50, in __getattr__\n",
      "    module = self._load()\n",
      "  File \"/home/mi/zpz/anaconda3/envs/tf_2.0_gpu/lib/python3.7/site-packages/tensorflow/__init__.py\", line 44, in _load\n",
      "    module = _importlib.import_module(self.__name__)\n",
      "  File \"/home/mi/zpz/anaconda3/envs/tf_2.0_gpu/lib/python3.7/importlib/__init__.py\", line 127, in import_module\n",
      "    return _bootstrap._gcd_import(name[level:], package, level)\n",
      "  File \"<frozen importlib._bootstrap>\", line 1006, in _gcd_import\n",
      "  File \"<frozen importlib._bootstrap>\", line 983, in _find_and_load\n",
      "  File \"<frozen importlib._bootstrap>\", line 965, in _find_and_load_unlocked\n",
      "ModuleNotFoundError: No module named 'tensorflow_core.estimator'\n"
     ]
    }
   ],
   "source": [
    "\n",
    "\n",
    "#kaggle跑完后 优化的模型  添加了参数增加拟合能力 同时失活 防止过拟合\n",
    "\n",
    "model = tf.keras.Sequential()\n",
    "model.add(tf.keras.layers.Conv2D(64,(3,3),input_shape=train_images.shape[1:],activation=\"relu\",padding=\"same\"))\n",
    "model.add(tf.keras.layers.Conv2D(64,(3,3),activation=\"relu\",padding=\"same\"))\n",
    "model.add(tf.keras.layers.MaxPool2D()) #默认缩小一半\n",
    "model.add(tf.keras.layers.Dropout(0.5)) \n",
    "model.add(tf.keras.layers.Conv2D(128,(3,3),activation=\"relu\",padding=\"same\"))\n",
    "model.add(tf.keras.layers.Conv2D(128,(3,3),activation=\"relu\",padding=\"same\"))\n",
    "model.add(tf.keras.layers.MaxPool2D()) #默认缩小一半\n",
    "model.add(tf.keras.layers.Dropout(0.5)) \n",
    "model.add(tf.keras.layers.Conv2D(256,(3,3),activation=\"relu\",padding=\"same\"))\n",
    "model.add(tf.keras.layers.Conv2D(256,(3,3),activation=\"relu\",padding=\"same\"))\n",
    "model.add(tf.keras.layers.MaxPool2D())\n",
    "model.add(tf.keras.layers.Dropout(0.5)) \n",
    "model.add(tf.keras.layers.Conv2D(512,(3,3),activation=\"relu\",padding=\"same\"))\n",
    "model.add(tf.keras.layers.Conv2D(512,(3,3),activation=\"relu\",padding=\"same\"))\n",
    "model.add(tf.keras.layers.Dropout(0.5)) \n",
    "model.add(tf.keras.layers.GlobalAveragePooling2D())#全居池化\n",
    "model.add(tf.keras.layers.Dense(256,activation=\"relu\"))\n",
    "model.add(tf.keras.layers.Dense(10,activation=\"softmax\"))"
   ]
  },
  {
   "cell_type": "code",
   "execution_count": null,
   "id": "f122a878",
   "metadata": {},
   "outputs": [],
   "source": [
    "#kaggle  GPU准确率提高很好"
   ]
  }
 ],
 "metadata": {
  "kernelspec": {
   "display_name": "Python 3 (ipykernel)",
   "language": "python",
   "name": "python3"
  },
  "language_info": {
   "codemirror_mode": {
    "name": "ipython",
    "version": 3
   },
   "file_extension": ".py",
   "mimetype": "text/x-python",
   "name": "python",
   "nbconvert_exporter": "python",
   "pygments_lexer": "ipython3",
   "version": "3.7.11"
  }
 },
 "nbformat": 4,
 "nbformat_minor": 5
}
